Workbook
Name Biz_Permitted: Parameters!$D$6:$D$10
Name Caps_Grade: Parameters!$A$6:$A$10
Name Caps_Metro: Parameters!$B$6:$B$10
Name Caps_NonMetro: Parameters!$C$6:$C$10
Name Expired_Days: Parameters!$B$22
Name Late_Days: Parameters!$B$21
Name Lbl_Alcohol: Parameters!$B$29
Name Lbl_Assumption: Parameters!$B$41
Name Lbl_BizNo: Parameters!$B$34
Name Lbl_Business: Parameters!$B$32
Name Lbl_Comp: Parameters!$B$36
Name Lbl_Definite: Parameters!$B$40
Name Lbl_Expired: Parameters!$B$39
Name Lbl_Flight: Parameters!$B$26
Name Lbl_Hotel: Parameters!$B$27
Name Lbl_Late: Parameters!$B$38
Name Lbl_Meals: Parameters!$B$28
Name Lbl_Metro: Parameters!$B$30
Name Lbl_NA: Parameters!$B$37
Name Lbl_NeedApproval: Parameters!$B$58
Name Lbl_NeedDays: Parameters!$B$57
Name Lbl_NeedNights: Parameters!$B$56
Name Lbl_NonMetro: Parameters!$B$31
Name Lbl_NoReceipt: Parameters!$B$33
Name Lbl_Viol: Parameters!$B$35
Name Limit_Metro: Parameters!$B$14
Name Limit_NonMetro: Parameters!$B$15
Name Min_Days_Booked: Parameters!$B$19
Name Receipt_Threshold: Parameters!$B$20
Name Rule_Basis: Parameters!$B$45:$B$52
Name Rule_IDs: Parameters!$A$45:$A$52
Name Test_Synth: Test_Cases!$D$3

Sheet Task Brief
A1: T06 Expense claim policy checker
A2: Mini project | 30 marks | Build something with free LLM tools
A4: Task ID | B4: T06
A5: Task | B5: Expense claim policy checker
A6: Theme | B6: No-code apps & dashboards
A7: Suggested free tools | B7: Gemini Canvas, ChatGPT Canvas or Claude (free) to generate the app; Excel / Google Sheets to verify numbers
A8: What students do | B8: 1. Convert the travel policy rules into checks with the help of an LLM. 2. Build a tool that flags each claim as compliant or violation, with the rule broken. 3. Manually audit 30 flagged claims to measure false alarms. 4. Summarise the top violation types for the CFO.
A9: Deliverables | B9: Checker tool; audit sheet; CFO summary; AI-use log
A10: Dataset in this file | B10: 400 expense claims + 15 travel policy rules - 'Claims' sheet: 400 rows x 14 columns - 'Policy Rules' sheet: 15 rows x 3 columns
A11: About the data | B11: All data is synthetic and created for teaching; companies, people and figures are fictional. Treat it as if it were real business data. If a 'Gold Labels (evaluation)' sheet is present, do NOT give it to the AI tool - use it only at the end to measure your accuracy.
A12: Team size | B12: Individual (or pairs if your faculty allows)
A13: Responsible AI rules | B13: Use only free tools; never paste real personal or confidential data into public AI tools; verify every number the AI gives you; disclose AI-generated content.
A14: Submission | B14: 1) Build link / file / screen recording 2) This workbook with your outputs added as new sheets 3) Completed 'AI Use Log' sheet (minimum 15 entries) 4) 3-5 page report with recommendation and reflection
A16: Evaluation rubric (30 marks)
A17: Criterion | B17: What is assessed | C17: Marks | D17: Excellent | E17: Good | F17: Fair | G17: Poor
A18: 1. Working build | B18: Tool / bot / app / automation works end to end on the provided data; link, file or screen recording submitted | C18: 8 | D18: Runs fully (7-8) | E18: Minor gaps (5-6) | F18: Partly working (3-4) | G18: Not working (0-2)
A19: 2. Correctness and verification | B19: Outputs checked against the data or gold labels; accuracy measured; errors found and fixed | C19: 7 | D19: Systematic checks with numbers (6-7) | E19: Some checks (4-5) | F19: Few checks (2-3) | G19: None (0-1)
A20: 3. Prompting and iteration | B20: Clear, structured prompts; at least 3 documented improvement rounds with reasons | C20: 5 | D20: Strong iteration (5) | E20: Some iteration (3-4) | F20: Mostly one-shot (2) | G20: No log (0-1)
A21: 4. Business insight and recommendation | B21: Specific, data-backed recommendation for the stated manager or customer | C21: 6 | D21: Actionable and quantified (6) | E21: Sound but generic (4-5) | F21: Descriptive only (2-3) | G21: Missing (0-1)
A22: 5. Documentation and reflection | B22: Complete AI-use log, limitations, responsible-AI notes and personal reflection | C22: 4 | D22: Complete and honest (4) | E22: Mostly complete (3) | F22: Thin (2) | G22: Missing (0-1)
A23: Total | C23: =SUM(C18:C22) -> 30

Sheet Claims
A1: claim_id | B1: employee_id | C1: employee_name | D1: grade | E1: expense_type | F1: city | G1: city_class | H1: amount_inr | I1: trip_end_date | J1: claim_submitted_date | K1: receipt_attached | L1: purpose_note | M1: days_booked_before_flight | N1: flight_class
A2: EXP00001 | B2: EMP003 | C2: Rahul Kaur | D2: M3 | E2: Meals/DA | F2: Jaipur | G2: Non-metro | H2: 1358 | I2: 45804 | J2: 45806 | K2: No | L2: Client dinner
A3: EXP00002 | B3: EMP055 | C3: Aditya Kulkarni | D3: M1 | E3: Hotel | F3: Jaipur | G3: Non-metro | H3: 8815 | I3: 45951 | J3: 45956 | K3: Yes | L3: Client dinner
A4: EXP00003 | B4: EMP033 | C4: Deepika Desai | D4: M2 | E4: Local Cab | F4: Mumbai | G4: Metro | H4: 1354 | I4: 45945 | J4: 46015 | K4: No | L4: Vendor meeting
A5: EXP00004 | B5: EMP055 | C5: Aditya Kulkarni | D5: M1 | E5: Hotel | F5: Chennai | G5: Metro | H5: 8155 | I5: 46041 | J5: 46050 | K5: Yes | L5: Site visit
A6: EXP00005 | B6: EMP009 | C6: Aditya D'Souza | D6: M5 | E6: Alcohol | F6: Mumbai | G6: Metro | H6: 2069 | I6: 45867 | J6: 45881 | K6: Yes | L6: Airport cab
A7: EXP00006 | B7: EMP024 | C7: Gurpreet Khan | D7: M3 | E7: Flight | F7: Nashik | G7: Non-metro | H7: 6289 | I7: 45836 | J7: 45845 | K7: Yes | L7: Team meeting | M7: 3 | N7: Economy
A8: EXP00007 | B8: EMP010 | C8: Imran Jadhav | D8: M1 | E8: Stationery | F8: Indore | G8: Non-metro | H8: 966 | I8: 45996 | J8: 45998 | K8: Yes | L8: Team meeting
A9: EXP00008 | B9: EMP034 | C9: Simran Mukherjee | D9: M2 | E9: Client Entertainment | F9: Delhi | G9: Metro | H9: 8867 | I9: 45903 | J9: 45923 | K9: Yes | L9: Flight booked
A10: EXP00009 | B10: EMP005 | C10: Yash Patil | D10: M1 | E10: Hotel | F10: Kochi | G10: Non-metro | H10: 11611 | I10: 45877 | J10: 45882 | K10: Yes | L10: Hotel stay
A11: EXP00010 | B11: EMP018 | C11: Vivaan Kulkarni | D11: M1 | E11: Client Entertainment | F11: Kochi | G11: Non-metro | H11: 7668 | I11: 45993 | J11: 45998 | K11: No | L11: Vendor meeting
A12: EXP00011 | B12: EMP028 | C12: Rajesh Sharma | D12: M2 | E12: Local Cab | F12: Indore | G12: Non-metro | H12: 1061 | I12: 45978 | J12: 45983 | K12: Yes | L12: Client dinner
A13: EXP00012 | B13: EMP055 | C13: Aditya Kulkarni | D13: M1 | E13: Meals/DA | F13: Mumbai | G13: Metro | H13: 1189 | I13: 45965 | J13: 46000 | K13: Yes | L13: Conference
A14: EXP00013 | B14: EMP012 | C14: Sandeep Verma | D14: M1 | E14: Local Cab | F14: Indore | G14: Non-metro | H14: 157 | I14: 46058 | J14: 46093 | K14: Yes | L14: Vendor meeting
A15: EXP00014 | B15: EMP042 | C15: Rahul Mishra | D15: M2 | E15: Flight | F15: Mumbai | G15: Metro | H15: 17576 | I15: 45944 | J15: 45949 | K15: Yes | L15: Flight booked | M15: 0 | N15: Economy
A16: EXP00015 | B16: EMP019 | C16: Kavya Pawar | D16: M2 | E16: Local Cab | F16: Bengaluru | G16: Metro | H16: 735 | I16: 45751 | J16: 45756 | K16: Yes | L16: Site visit
A17: EXP00016 | B17: EMP039 | C17: Farhan Khan | D17: M3 | E17: Local Cab | F17: Chennai | G17: Metro | H17: 2109 | I17: 45806 | J17: 45811 | K17: Yes | L17: Conference
A18: EXP00017 | B18: EMP039 | C18: Farhan Khan | D18: M3 | E18: Flight | F18: Nashik | G18: Non-metro | H18: 4019 | I18: 45950 | J18: 45985 | K18: Yes | L18: Flight booked | M18: 12 | N18: Economy
A19: EXP00018 | B19: EMP013 | C19: Suresh Mishra | D19: M2 | E19: Meals/DA | F19: Kochi | G19: Non-metro | H19: 944 | I19: 45801 | J19: 45815 | K19: Yes | L19: Team meeting
A20: EXP00019 | B20: EMP005 | C20: Yash Patil | D20: M1 | E20: Hotel | F20: Bengaluru | G20: Metro | H20: 11637 | I20: 45924 | J20: 45959 | K20: Yes | L20: Airport cab
A21: EXP00020 | B21: EMP052 | C21: Anil Pawar | D21: M2 | E21: Stationery | F21: Bengaluru | G21: Metro | H21: 1374 | I21: 45829 | J21: 45838 | K21: Yes | L21: Team meeting
A22: EXP00021 | B22: EMP057 | C22: Yash Gupta | D22: M3 | E22: Client Entertainment | F22: Indore | G22: Non-metro | H22: 5918 | I22: 45827 | J22: 45832 | K22: Yes | L22: Flight booked
A23: EXP00022 | B23: EMP002 | C23: Simran Gupta | D23: M2 | E23: Flight | F23: Bengaluru | G23: Metro | H23: 12701 | I23: 45878 | J23: 45887 | K23: No | L23: Flight booked | M23: 19 | N23: Economy
A24: EXP00023 | B24: EMP023 | C24: Manish Jadhav | D24: M5 | E24: Alcohol | F24: Mumbai | G24: Metro | H24: 2935 | I24: 45965 | J24: 45974 | K24: Yes | L24: Hotel stay
A25: EXP00024 | B25: EMP022 | C25: Fatima Mukherjee | D25: M1 | E25: Train | F25: Nashik | G25: Non-metro | H25: 2387 | I25: 45828 | J25: 45830 | K25: Yes | L25: Team meeting
A26: EXP00025 | B26: EMP052 | C26: Anil Pawar | D26: M2 | E26: Stationery | F26: Jaipur | G26: Non-metro | H26: 728 | I26: 45973 | J26: 45978 | K26: Yes | L26: Client dinner
A27: EXP00026 | B27: EMP010 | C27: Imran Jadhav | D27: M1 | E27: Meals/DA | F27: Kochi | G27: Non-metro | H27: 2160 | I27: 45751 | J27: 45756 | K27: Yes | L27: Team meeting
A28: EXP00027 | B28: EMP016 | C28: Riya Khan | D28: M3 | E28: Train | F28: Bengaluru | G28: Metro | H28: 2787 | I28: 45813 | J28: 45833 | K28: Yes | L28: Team meeting
A29: EXP00028 | B29: EMP055 | C29: Aditya Kulkarni | D29: M1 | E29: Local Cab | F29: Delhi | G29: Metro | H29: 1233 | I29: 46021 | J29: 46030 | K29: Yes | L29: Conference
A30: EXP00029 | B30: EMP028 | C30: Rajesh Sharma | D30: M2 | E30: Alcohol | F30: Mumbai | G30: Metro | H30: 4803 | I30: 45769 | J30: 45774 | K30: Yes | L30: Conference
A31: EXP00030 | B31: EMP055 | C31: Aditya Kulkarni | D31: M1 | E31: Local Cab | F31: Jaipur | G31: Non-metro | H31: 1564 | I31: 45925 | J31: 45927 | K31: No | L31: Team meeting
A32: EXP00031 | B32: EMP005 | C32: Yash Patil | D32: M1 | E32: Local Cab | F32: Bengaluru | G32: Metro | H32: 1971 | I32: 45902 | J32: 45907 | K32: Yes | L32: Team meeting
A33: EXP00032 | B33: EMP057 | C33: Yash Gupta | D33: M3 | E33: Flight | F33: Mumbai | G33: Metro | H33: 8594 | I33: 45962 | J33: 45967 | K33: Yes | L33: Team meeting | M33: 11 | N33: Economy
A34: EXP00033 | B34: EMP009 | C34: Aditya D'Souza | D34: M5 | E34: Hotel | F34: Bengaluru | G34: Metro | H34: 4231 | I34: 46034 | J34: 46036 | K34: Yes | L34: Airport cab
A35: EXP00034 | B35: EMP001 | C35: Meera Nair | D35: M2 | E35: Local Cab | F35: Indore | G35: Non-metro | H35: 157 | I35: 45761 | J35: 45775 | K35: Yes | L35: Conference
A36: EXP00035 | B36: EMP045 | C36: Nisha Sharma | D36: M4 | E36: Hotel | F36: Indore | G36: Non-metro | H36: 3894 | I36: 45762 | J36: 45782 | K36: Yes | L36: Conference
A37: EXP00036 | B37: EMP051 | C37: Harsh Chatterjee | D37: M2 | E37: Hotel | F37: Nashik | G37: Non-metro | H37: 14609 | I37: 45823 | J37: 45828 | K37: Yes | L37: Client dinner
A38: EXP00037 | B38: EMP059 | C38: Harpreet Pillai | D38: M3 | E38: Client Entertainment | F38: Bengaluru | G38: Metro | H38: 15200 | I38: 46042 | J38: 46112 | K38: Yes | L38: Client dinner
A39: EXP00038 | B39: EMP039 | C39: Farhan Khan | D39: M3 | E39: Flight | F39: Mumbai | G39: Metro | H39: 14773 | I39: 45812 | J39: 45847 | K39: Yes | L39: Airport cab | M39: 2 | N39: Economy
A40: EXP00039 | B40: EMP023 | C40: Manish Jadhav | D40: M5 | E40: Meals/DA | F40: Jaipur | G40: Non-metro | H40: 1613 | I40: 45961 | J40: 45970 | K40: Yes | L40: Airport cab
...

Sheet Policy Rules
A1: rule_id | B1: topic | C1: rule_text
A2: TP-01 | B2: Air travel | C2: Economy class for all grades on flights under 4 hours. Grade M4 and above may fly business class on flights over 4 hours.
A3: TP-02 | B3: Advance booking | C3: Flights must be booked at least 7 days before travel; later bookings need a written reason approved by the department head.
A4: TP-03 | B4: Train travel | C4: AC 2-tier for grades M1-M3 and AC 1st class for M4 and above.
A5: TP-04 | B5: Hotel limits - metro | C5: Maximum Rs 7,000 per night for M1-M2, Rs 10,000 for M3 and Rs 14,000 for M4 and above in metro cities.
A6: TP-05 | B6: Hotel limits - non-metro | C6: Maximum Rs 4,500 per night for M1-M2, Rs 6,500 for M3 and Rs 9,000 for M4 and above in other cities.
A7: TP-06 | B7: Daily allowance | C7: Rs 1,200 per day in metro cities and Rs 900 per day elsewhere, covering meals and incidentals.
A8: TP-07 | B8: Local conveyance | C8: App-based cabs or auto-rickshaws; self-drive rental cars need prior approval.
A9: TP-08 | B9: Alcohol | C9: Alcohol is not reimbursable under any circumstances.
A10: TP-09 | B10: Receipts | C10: Original receipts are required for every expense above Rs 500.
A11: TP-10 | B11: Claim deadline | C11: Claims must be submitted within 15 days of returning; claims older than 60 days are rejected.
A12: TP-11 | B12: International travel | C12: Needs approval from the business unit head and CFO at least 21 days before departure.
... A16: TP-15 | B16: Spouse travel | C16: Travel costs of a spouse or family member are not reimbursable.

Sheet Data Dictionary
A1: sheet | B1: column | C1: data_type | D1: example_value | E1: non_empty_values | F1: distinct_values
A2: Claims | B2: claim_id | C2: Text | D2: EXP00001 | E2: 400 | F2: 400
A3: Claims | B3: employee_id | C3: Text | D3: EMP003 | E3: 400 | F3: 60
A4: Claims | B4: employee_name | C4: Text | D4: Rahul Kaur | E4: 400 | F4: 60
A5: Claims | B5: grade | C5: Text | D5: M3 | E5: 400 | F5: 5
A6: Claims | B6: expense_type | C6: Text | D6: Meals/DA | E6: 400 | F6: 8
A7: Claims | B7: city | C7: Text | D7: Jaipur | E7: 400 | F7: 8
A8: Claims | B8: city_class | C8: Text | D8: Non-metro | E8: 400 | F8: 2
A9: Claims | B9: amount_inr | C9: Decimal number | D9: 1358.0 | E9: 400 | F9: 388
A10: Claims | B10: trip_end_date | C10: Date/time | D10: 2025-05-27 | E10: 400 | F10: 241
A11: Claims | B11: claim_submitted_date | C11: Date/time | D11: 2025-05-29 | E11: 400 | F11: 234
A12: Claims | B12: receipt_attached | C12: Text | D12: No | E12: 400 | F12: 2
A13: Claims | B13: purpose_note | C13: Text | D13: Client dinner | E13: 400 | F13: 8
... A18: Policy Rules | B18: rule_text | C18: Text | D18: Economy class for all grades on flights under 4 hours. Grade M4 and above may fl | E18: 15 | F18: 15

Sheet AI Use Log
A1: AI Use Log - fill one row per prompt (minimum 15). Yellow cells are for you to fill.
A2: Evidence = shared chat link or screenshot file name. Keep rejected outputs too - they earn marks under 'Prompting and iteration'.
A3: # | B3: date | C3: tool | D3: model / mode | E3: settings used (if any) | F3: prompt (exact text) | G3: what the output did well / badly | H3: what I changed next and why | I3: kept or rejected | J3: evidence link / file
A4: 1 | B4: 46296 | C4: Claude | D4: Claude Sonnet 5, claude.ai chat | F4: You are a business analyst supporting an MBA student. I am doing the mini project 'T06 Expense claim policy checker' (30 marks, individual). I am pasting the Task Brief, rubric, the 15 Policy Rules, the Data Dictionary and the Claims column headers with a few sample rows. Please analyse the assignment only and do not build anything yet. Cover: (1) what I must deliver and the four task steps; (2) the submission requirements and the rubric with marks; (3) constraints such as free tools only and responsible-AI rules; (4) which of the 15 policy rules appear testable with the 14 Claims columns, which are only partly testable and which cannot be tested, naming the missing fields; (5) dependencies between the steps; (6) risks, ambiguities and missing information; (7) a proposed execution strategy. Use only the text I provide, and where something is not stated, write 'Not stated - needs my confirmation' instead of assuming. Present the answer as short headed sections with one table for the rule-testability check (rule ID, testable / partial / not testable, fields used, what is missing). | G4: Covered deliverables, rubric, constraints and a rule-testability table (3 testable, 5 partial, 7 not testable). Missed that TP-10 has two thresholds (15 and 60 days) and the boundary wording of TP-02 and TP-09. | H4: Added the TP-10 two-threshold point and the exact boundaries to the Session 2 and 3 prompts. | I4: Kept | J4: https://drive.google.com/file/d/1W71MqVg8apF8terBuliPgteR6RNnApUs/view?usp=drivesdk
A5: 2 | B5: 46296 | C5: Claude | D5: Claude Sonnet 5, claude.ai chat | F5: You are a data analyst. Context: I am building an expense claim policy checker for the T06 mini project. I have attached the Claims sheet (400 rows, 14 columns, synthetic data) and its Data Dictionary. Task: profile the data before any policy checks. Report the row count, column types and blank counts, noting that days_booked_before_flight and flight_class should be filled only for Flight rows. Report counts by expense_type, grade, city_class and receipt_attached, and amount ranges by expense_type. Also report how the two date columns are stored, the distribution of days between trip_end_date and claim_submitted_date (minimum, median, maximum, and how many gaps exceed 15 and 60 days), and any anomalies, such as purpose_note values that do not match the expense_type. Constraints: use only the data I attached; do not judge policy compliance yet; explain how each number was calculated so I can reproduce it in Excel; label anything you are unsure of as 'to verify'. Output: a short findings list plus three small tables (counts, amount ranges, date-gap summary). | G5: Counts, amount ranges and date gaps were all correct when recalculated independently. Useful findings: amounts are whole rupees, only 7 distinct date gaps exist, purpose_note does not match expense_type. Hedged unsure points as 'to verify'. | H5: Used the verified counts in Session 3 and excluded purpose_note from all rule logic. | I5: Kept | J5: https://drive.google.com/file/d/1Wt6bq82FxgyAaUMRNJxh82bwbGaMyN32/view?usp=drivesdk
A6: 3 | B6: 46296 | C6: Claude | D6: Claude Sonnet 5, claude.ai chat | F6: You are a compliance analyst. Context: the T06 expense claim checker must apply the 15 travel policy rules (TP-01 to TP-15, pasted below) to the Claims columns: claim_id, employee_id, grade, expense_type, city, city_class, amount_inr, trip_end_date, claim_submitted_date, receipt_attached, purpose_note, days_booked_before_flight, flight_class. Verified data facts: the two flight columns are filled only for the 58 Flight rows; amount_inr is a whole-rupee amount per claim; there is no nights, days, flight-duration, train-class or approval field; purpose_note does not match expense_type and must not be used. Task: convert each rule into a check using these decisions I have made. (1) Claim status is only Compliant or Violation, with a separate basis column, Definite or Assumption-based; a claim breaking several rules lists all rule IDs. (2) TP-01: Business class for grades M1 to M3 is a violation; Economy is compliant; Business for M4 and above is treated as compliant because duration is unknown. (3) TP-02: Flight rows only, days_booked_before_flight below 7 is a violation, exactly 7 is compliant, basis Assumption-based because the approval exception is not recorded. (4) TP-04 and TP-05: for Hotel rows compare amount_inr with the nightly cap for the grade and city_class, treating each claim as one night, basis Assumption-based. (5) TP-06: for Meals/DA rows compare amount_inr with Rs 1,200 for Metro or Rs 900 for Non-metro, treating each claim as one day, basis Assumption-based. (6) TP-08: every Alcohol row is a violation. (7) TP-09: receipt_attached = No and amount_inr above 500 is a violation; exactly 500 is compliant. (8) TP-10: gap = claim_submitted_date minus trip_end_date in calendar days; above 15 is a violation labelled Late; above 60 is a violation labelled Expired; one rule ID for both. (9) TP-03, TP-07 and TP-11 to TP-15 cannot be tested with these columns; list them as Not checked with the missing field, never as compliant. Stationery and Client Entertainment have no cap, so only TP-09 and TP-10 apply to them. For every rule give the check in plain English, columns used, applies-to expense types, exact boundary logic, violation message naming the rule ID, basis, and testability status. Constraints: apply my decisions exactly; do not add rules, fields or assumptions; if any decision contradicts the rule text, say so instead of changing it; do not calculate counts from the data. Output: one table with the columns Rule ID, Check in plain English, Columns used, Applies to, Logic and boundary, Violation message, Basis, Testability, followed by a short list of any contradictions or gaps you notice. Policy rules: TP-01 Air travel: Economy class for all grades on flights under 4 hours. Grade M4 and above may fly business class on flights over 4 hours. TP-02 Advance booking: Flights must be booked at least 7 days before travel; later bookings need a written reason approved by the department head. TP-03 Train travel: AC 2-tier for grades M1-M3 and AC 1st class for M4 and above. TP-04 Hotel limits - metro: Maximum Rs 7,000 per night for M1-M2, Rs 10,000 for M3 and Rs 14,000 for M4 and above in metro cities. TP-05 Hotel limits - non-metro: Maximum Rs 4,500 per night for M1-M2, Rs 6,500 for M3 and Rs 9,000 for M4 and above in other cities. TP-06 Daily allowance: Rs 1,200 per day in metro cities and Rs 900 per day elsewhere, covering meals and incidentals. TP-07 Local conveyance: App-based cabs or auto-rickshaws; self-drive rental cars need prior approval. TP-08 Alcohol: Alcohol is not reimbursable under any circumstances. TP-09 Receipts: Original receipts are required for every expense above Rs 500. TP-10 Claim deadline: Claims must be submitted within 15 days of returning; claims older than 60 days are rejected. TP-11 International travel: Needs approval from the business unit head and CFO at least 21 days before departure. TP-12 Personal extension: Personal days added to a business trip are at the employee's cost, and the ticket fare must not exceed the business-only fare. TP-13 Approval chain: Domestic trips need manager approval; trips costing above Rs 1,00,000 also need the department head. TP-14 Cancellation: Cancellation charges caused by business reasons are reimbursed; charges from personal reasons are recovered. TP-15 Spouse travel: Travel costs of a spouse or family member are not reimbursable. | G6: Table matched the rule text, caps and boundaries exactly and applied my decisions. Listed useful contradictions (TP-01 stricter reading, TP-02 approved exception, per-night/per-day assumptions). Left basis undefined for Compliant claims and for mixed Definite/Assumption claims. | H6: Resolved the open points: exactly at cap is Compliant, claim basis is Definite if any broken rule is Definite, Basis blank for Compliant. Carried into the Session 4 register. | I6: Partly kept | J6: https://drive.google.com/file/d/1eQCyXQ4rKojceAHu2xyuftqs_JpeVHGb/view?usp=drivesdk
A7: 4 | B7: 46296 | C7: Claude | D7: Claude Sonnet 5, claude.ai chat | F7: You are a policy analyst. Context: I have a final rule-to-check specification for the T06 expense claim checker (pasted below) and the attached Claims sheet with 400 rows (columns: claim_id, employee_id, employee_name, grade, expense_type, city, city_class, amount_inr, trip_end_date, claim_submitted_date, receipt_attached, purpose_note, days_booked_before_flight, flight_class). Task: (1) create an Assumptions Register with one row per assumption: one claim equals one hotel night (TP-04 and TP-05); one claim equals one day (TP-06); a claim exactly at a cap or limit is Compliant; TP-02 late bookings are flagged even though an approved exception may exist; trip_end_date is treated as the return date (TP-10); Business class for grades M4 and above is Compliant because flight duration is unknown; claim-level basis is Definite if any broken rule is Definite, otherwise Assumption-based; 'Compliant' means no violation found among the 8 checked rules (TP-01, 02, 04, 05, 06, 08, 09, 10) while 7 rules (TP-03, 07, 11 to 15) are Not checked. For each assumption give what it affects, whether it is likely to over-flag or under-flag, and how my audit of 30 flagged claims could test it. (2) For Hotel rows and Meals/DA rows, compute how many claims would be flagged if each claim covered 1, 2 or 3 nights (hotel cap multiplied by 1, 2, 3) or days (daily limit multiplied by 1, 2, 3), and show the method so I can reproduce it in Excel. Constraints: do not change or challenge my decisions; do not propose alternative rules; use only the attached data and the specification; if a count cannot be computed from the data, say so; leave a line 'My confirmation: ______' under each assumption. Output: the register as a table with columns Assumption, Rule affected, Effect on flags, Over- or under-flag, How the audit can test it, My confirmation; then one small sensitivity table with the counts and the Excel method. Specification: TP-01 | Flight class allowed for the grade | Columns: expense_type, grade, flight_class | Flight rows | grade M1, M2, M3 with flight_class Business is a Violation; Economy is Compliant; grade M4, M5 with Business is Compliant (duration unknown) | Basis: Definite for M1 to M3 Business | Partial TP-02 | Flight booked at least 7 days ahead | Columns: expense_type, days_booked_before_flight | Flight rows | days_booked_before_flight below 7 is a Violation; 7 or more is Compliant | Basis: Assumption-based (approval exception not recorded) | Partial TP-03 | Train class for the grade | No columns | Train rows | Not checked, no train-class field | Not testable TP-04 | Metro hotel cost within nightly cap | Columns: expense_type, city_class, grade, amount_inr | Hotel rows, Metro | One claim treated as one night; caps M1-M2 Rs 7,000, M3 Rs 10,000, M4-M5 Rs 14,000; amount above cap is a Violation; equal to cap is Compliant | Assumption-based | Partial TP-05 | Non-metro hotel cost within nightly cap | Columns: expense_type, city_class, grade, amount_inr | Hotel rows, Non-metro | One claim treated as one night; caps M1-M2 Rs 4,500, M3 Rs 6,500, M4-M5 Rs 9,000; amount above cap is a Violation; equal to cap is Compliant | Assumption-based | Partial TP-06 | Daily allowance within limit | Columns: expense_type, city_class, amount_inr | Meals/DA rows | One claim treated as one day; limit Rs 1,200 Metro, Rs 900 Non-metro; amount above limit is a Violation; equal is Compliant | Assumption-based | Partial TP-07 | Cab type | No columns | Local Cab rows | Not checked, no cab-type or approval field | Not testable TP-08 | Alcohol never reimbursable | Column: expense_type | Alcohol rows | Every Alcohol row is a Violation | Definite | Testable TP-09 | Receipt required above Rs 500 | Columns: receipt_attached, amount_inr | All expense types | receipt_attached No and amount above 500 is a Violation; exactly 500 is Compliant | Definite | Testable TP-10 | Claim submitted on time | Columns: trip_end_date, claim_submitted_date | All expense types | gap = claim_submitted_date minus trip_end_date in calendar days; gap above 60 is a Violation labelled Expired; gap above 15 up to 60 is a Violation labelled Late; gap 15 or less is Compliant | Definite | Testable TP-11 to TP-15 | International approvals, personal extension, approval chain, cancellation, spouse travel | No columns | n/a | Not checked: the required fields (international flag, approvals, personal days, trip cost, cancellation flag, traveller relationship) are not in the data | Not testable Stationery and Client Entertainment rows are assessed only under TP-09 and TP-10. | G7: Register and sensitivity counts were correct (hotel flagged 49/19/12, Meals/DA 55/12/0) with usable Excel formulas. Weak point: suggested checking TP-10 against a confirmed return date, which the data cannot support. | H7: Signed off the assumptions (confirmation lines) and used the sensitivity numbers as the basis for the limitations section. | I7: Partly kept | J7: https://drive.google.com/file/d/1CD79v4L7Zv7fzJBP8N0emEmw0vS5aHGG/view?usp=drivesdk
A8: 5 | B8: 46296 | C8: Claude | D8: Claude Sonnet 5, claude.ai chat | F8: Act as a QA analyst. Using the attached rule-to-check specification and assumptions register (with my confirmations), give the evaluation order for the Checker and a test-case table for every checked rule (TP-01, 02, 04, 05, 06, 08, 09, 10): pass, fail and boundary cases such as exactly 7 days, 15 days, Rs 500 and cap amounts. Use real claim_ids from the Claims sheet where one exists, otherwise write 'synthetic case'. Do not add rules, change my decisions or compute totals. Table columns: Test ID, Rule ID, Input, Expected result, Claim ID or synthetic. | G8: Produced 50 test cases; every real claim_id and expected result was correct. It noted nothing was attached and used the earlier chat instead. Missing: boundary tests for the M3/M4/M5 caps and TP-06 at Rs 901, and Basis for Compliant claims was undefined. | H8: Added five extra boundary tests (S-01 to S-05) and decided Basis stays blank for Compliant claims. | I8: Partly kept | J8: https://drive.google.com/file/d/1XnC5o3JAkzC9mgHl7nLOzaqcMxW__UWO/view?usp=drivesdk
A9: 6 | B9: 46296 | C9: Claude | D9: Claude Sonnet 5, claude.ai chat | F9: Add two sheets to the attached T06 workbook, leaving the original sheets untouched: Parameters (hotel caps by grade and city class, daily limits, and the 7-day, Rs 500 and 15/60-day thresholds, one input cell each) and Checker (one row per claim, 400 rows). Columns: one check per rule TP-01, 02, 04, 05, 06, 08, 09, 10, then Status (Compliant/Violation), Rules broken (all IDs, using TEXTJOIN), TP-10 Late/Expired label, and Basis (blank for Compliant). Use formulas only, referencing Parameters, with no macros and no hardcoded numbers. Follow the attached specification exactly. List the 7 Not checked rules below the table. Return the file. | G9: Workbook recalculated with 0 formula errors; all 400 rows matched an independent recalculation (231 Violation, 169 Compliant; Basis 139 Definite / 92 Assumption-based). Formulas reference Parameters and named ranges. | H9: Moved to running the test cases against the Checker in Session 7. | I9: Kept | J9: https://drive.google.com/file/d/1VFzKxVW_Cw3RAVcquB7ViRUV--emwAzz/view?usp=drivesdk
A10: 7 | B10: 46297 | C10: Claude | D10: Claude Sonnet 5, claude.ai chat | F10: Attached is workbook v1 with the Checker sheet. Add a Test_Cases sheet from the attached test-case table (including my S-01 to S-05 additions): one row per test with the input fields, the expected result, and the actual result computed with the same formulas and Parameters as the Checker, plus a PASS/FAIL column and a pass count. For real claim_ids, look up the Checker row; for synthetic cases, enter the input fields. List every mismatch with cause and fix. Change only what is needed and do not alter my decisions. Return workbook v1.1 and a short change list. | G10: All 50 tests with expected results PASS, 0 FAIL; Checker and Parameters unchanged. S-01 to S-05 left as 'Awaiting input' because they were not attached. Limitation: synthetic cases re-apply the same formulas rather than running through the Checker row. | H10: Logged as Improvement Round 1: tests run, no defects found, no change made. Update: S-01 to S-05 were completed afterwards (M3/M4/M5 caps and TP-06 at Rs 901); all 55 tests now PASS. | I10: Kept | J10: https://drive.google.com/file/d/1SW3_wxUlOD6l_P4Kz9_lZYJBWTAkCtev/view?usp=drivesdk
A11: 8 | B11: 46297 | C11: Claude | D11: Claude Sonnet 5, claude.ai chat | F11: Improve the attached workbook v1.1 without changing the approved logic. Add a Summary sheet using COUNTIFS on the Checker: violations per rule (with each rule's basis), by expense_type and by grade, plus total flagged and compliant claims. Add an AutoFilter and frozen headers on the Checker, and keep the 'Rules not checked' list with the missing field for each rule. Use formulas only, referencing the Checker, with no hardcoded results. Return workbook v2 and a short change list. | G11: Summary figures matched my recount (231 flagged, per-rule hits 7/18/18/31/55/12/60/78, by expense type and grade). Checker logic unchanged. AutoFilter and frozen headers added. | H11: Logged as Improvement Round 2: Summary sheet and AutoFilter added, logic unchanged. | I11: Kept | J11: https://drive.google.com/file/d/1OUXjArduNqnCLaQnWy6w0sk8O4o-L5CJ/view?usp=drivesdk
A12: 9 | B12: 46297 | C12: Claude | D12: Claude Sonnet 5, claude.ai chat | F12: In the attached workbook v2, add a Verification sheet. For each checked rule (TP-01, 02, 04, 05, 06, 08, 09, 10), recompute the violation count directly from the raw Claims columns and Parameters using COUNTIFS or SUMPRODUCT, without using the Checker columns. Also recompute total flagged claims and the Definite versus Assumption-based split independently. Build a reconciliation table: Rule ID, Independent count, Checker count, Difference, Explanation. Do not change the Checker logic. Return workbook v2.1 and a short change list. | G12: All 16 reconciliation lines show difference 0. Limitation: both methods read the same Parameters, so it tests the formulas but not the policy values; two lines are derived by subtraction. | H12: Logged as Improvement Round 3: verification found 0 differences, no logic changed. | I12: Rejected | J12: https://drive.google.com/file/d/1kRXyZStfuVYfpxWSVSGO5iIN-pVaT0ak/view?usp=drivesdk
A13: 10 | B13: 46297 | C13: Claude | D13: Claude Sonnet 5, claude.ai chat | F13: You are an audit supervisor. Context: the attached workbook v2.1 has a Checker that flags 231 of 400 claims (rule flags: TP-01 7, TP-02 18, TP-04 18, TP-05 31, TP-06 55, TP-08 12, TP-09 60, TP-10 78; 139 claims have a Definite basis and 92 are Assumption-based only). Task: compare three ways to pick 30 flagged claims for a manual audit (simple random, stratified by rule, focused on Assumption-based flags), giving pros, cons and the false-alarm statistic each supports, then test my choice and verdict definitions for weaknesses. My choice: stratified by rule, with 30 claims = TP-01 3, TP-02 3, TP-04 3, TP-05 4, TP-06 4, TP-08 3, TP-09 5, TP-10 5, picked at random within each rule, no claim picked twice. My justification: rule sizes differ a lot (7 flags for TP-01 versus 78 for TP-10), so a simple random sample would include about one TP-01 claim on average and could miss TP-01 or TP-08 entirely; stratifying makes sure every rule is audited. I accept that small rules are over-represented, so I will report false alarms per rule and overall, say the overall rate is not a proportional estimate, and state that the audit measures false alarms only, not missed violations. Verdicts: True violation (breaks the policy text), False alarm (policy text and claim row show no breach), Cannot verify (depends on missing data such as nights, days or approval). Constraints: the brief only says 'audit 30 flagged claims'; do not select any claims yet; do not change my choice, only point out weaknesses. Output: a comparison table, a short critique of my choice, and the final verdict definitions. | G13: Comparison and probabilities were correct (about 37% chance of no TP-01 claim under simple random). Strong critique: False alarm is almost unreachable for TP-02/04/05/06, strata of 3 to 5 are tiny, the audit unit needs defining. Minor wording slip: said 92 claims or 122 rule flags (122 claims carry an Assumption-based flag, 92 are Assumption-only). | H13: Chose stratified sampling by rule with the 3/3/3/4/4/3/5/5 allocation; adopted verdict definitions with reason codes (CV-NIGHTS, CV-DAYS, CV-APPROVAL, CV-RETURN, CV-ORIGINAL); decided not to treat the Session 3 assumptions as facts in the audit. | I13: Kept | J13: https://drive.google.com/file/d/192Iy22-_DIG-knr-d5QT4vAdQc_O_i00/view?usp=drivesdk
A14: 11 | B14: 46297 | C14: Claude | D14: Claude Sonnet 5, claude.ai chat | F14: Add an Audit sheet to the attached workbook v2.1 with 30 flagged claims, stratified by rule as decided: TP-01 3, TP-02 3, TP-04 3, TP-05 4, TP-06 4, TP-08 3, TP-09 5, TP-10 5. Draw at random with a recorded seed, smallest strata first, no claim twice, and store the selected IDs as values, not live RAND(). Columns: Claim ID, all claim fields, audited rule, the exact policy rule text from Policy Rules, then blank columns My verdict (True violation / False alarm / Cannot verify), Reason code (CV-NIGHTS, CV-DAYS, CV-APPROVAL, CV-RETURN, CV-ORIGINAL), and My reason; put the Checker's own message in the last column. Do not fill any verdict. | G14: Audit sheet created with 30 distinct flagged claims and the correct allocation; seed 20261001 recorded and the draw reproduced exactly when re-run. Verdict columns correctly left blank; exact policy text shown per claim. | H14: Audit verdicts, reason codes and reasons for all 30 claims were completed by me manually, checking each claim against the policy text and the claim fields. AI was not used to decide the verdicts; it was used afterwards only to challenge the audit design and assumptions (see Session 12). | I14: Kept | J14: https://drive.google.com/file/d/1xM6hmqKIAcgNDJO-w0VRN9awEVIsaTeL/view?usp=drivesdk
A15: 12 | B15: 46297 | C15: Claude | D15: Claude Sonnet 5, claude.ai chat | F15: Act as a data analyst. Attached is the audited workbook v2.3. The audit of 30 stratified flagged claims found 16 True violations (TP-01 3, TP-08 3, TP-09 5, TP-10 5), 0 False alarms and 14 Cannot verify (CV-APPROVAL 3 for TP-02, CV-NIGHTS 7 for TP-04/05, CV-DAYS 4 for TP-06). Using only the Audit sheet and Checker, report the confirmed false-alarm rate and its possible range, group the 14 Cannot-verify claims by rule and cause, and say whether each stems from data limits, rule design or policy wording. Separate observed facts from interpretations, do not use the Checker's messages as audit evidence, and make no recommendations beyond what the audit supports. Output: a short findings list and one table by rule. | G15: Counts and causes matched the Audit sheet: 0 of 30 confirmed false alarms, possible range 0% to 46.7%, 14 Cannot verify all from TP-02/04/05/06. Correctly separated facts from interpretation and warned that 0% is not clean evidence for the Assumption-based rules. | H15: Decided not to change any rule logic (audit found no error); instead add transparency columns, a missing-data count and a sensitivity table in Session 13. | I15: Partly kept | J15: https://drive.google.com/file/d/1L5OXZvgLt7bnQtMin5XgCDkzO9AxEr0v/view?usp=drivesdk
... A19: 16 | B19: 46298 | C19: Claude | D19: Claude Sonnet 5, claude.ai chat | F19: Act as a finance communications writer. Add a one-page, print-ready CFO_Summary sheet to the attached workbook v3.1. Pull every number from Summary, Analytics and Audit with formulas, and use my recommendation text below word for word. Include a headline, the top violation types by count and value (marked Definite or Assumption-based), the audit result (16 True violation, 0 False alarm, 14 Cannot verify), my recommendation, and a limits box (7 rules not checked, one-night/one-day and return-date assumptions, audit measures false alarms only, values are not savings). Do not add savings, targets or any figure not in the workbook. Return workbook v3.2. Enforce now the three Definite-basis rules the audit confirmed (16 of 16 decided flags): block alcohol claims (TP-08: 12 claims, Rs 42,600), require a receipt above Rs 500 (TP-09: 60 claims, Rs 3,39,018) and flag Business class for grades M1 to M3 (TP-01: 7 claims, Rs 91,597); counted once, these are 78 claims worth Rs 4,68,885. For late submission (TP-10: 78 claims, the most frequent flag), apply the policy's own 60-day rejection to the 15 claims over 60 days (Rs 1,01,153) and add a reminder before the 15-day limit; this assumes trip_end_date is the return date. Before enforcing TP-02, 04, 05 and 06, add nights, days and late-booking approval fields to the claim form: 122 of 279 rule flags (claims worth Rs 9,17,734) cannot be confirmed from today's data, and the audit could not verify any of the 14 audited flags from these rules. Track success by re-running this Checker on new claims and watching the flagged share (57.8% today). All figures are values of flagged claims, not savings. | G19: CFO_Summary built with live formulas, one-page print area, no errors; recommendation text matched exactly; top violation table and limits box correct. Other sheets unchanged. | H19: Moved on to drafting the report. | I19: Kept | J19: https://drive.google.com/file/d/1diUZWsNs0F1U9prnreS8vS5gnqDeM5xa/view?usp=drivesdk
A20: 17
A21: 18
A22: 19
A23: 20
A24: 21
A25: 22
A26: 23
A27: 24
A28: 25

Sheet Parameters
A1: Parameters - T06 Expense claim policy checker
A2: Blue cells are the inputs; every Checker formula reads them (named ranges). Values come from the Policy Rules sheet, except where the note says "your decision" (Session 3 / 4 decisions).
A4: 1. Hotel caps (INR per night) and Business class by grade [TP-04, TP-05, TP-01]
A5: Grade | B5: Metro cap (INR) | C5: Non-metro cap (INR) | D5: Business class permitted? | E5: Note
A6: M1 | B6: 7000 | C6: 4500 | D6: No | E6: Caps: TP-04 / TP-05 text. One claim = one night (your assumption).
A7: M2 | B7: 7000 | C7: 4500 | D7: No | E7: Business: M1-M3 not permitted (TP-01).
A8: M3 | B8: 10000 | C8: 6500 | D8: No
A9: M4 | B9: 14000 | C9: 9000 | D9: Yes | E9: M4 and above: Business treated as Compliant because flight duration is unknown (your decision).
A10: M5 | B10: 14000 | C10: 9000 | D10: Yes
A12: 2. Daily limits (INR per day) [TP-06]
A13: City class | B13: Daily limit (INR) | C13: Note
A14: =Lbl_Metro -> Metro | B14: 1200 | C14: TP-06. One claim = one day (your assumption). Amount above limit = Violation; equal = Compliant.
A15: =Lbl_NonMetro -> Non-metro | B15: 900 | C15: TP-06 ("elsewhere" = Non-metro).
A17: 3. Thresholds
A18: Threshold | B18: Value | C18: Rule | D18: Note
A19: Minimum days booked before flight | B19: 7 | C19: TP-02 | D19: Below = Violation; exactly this value = Compliant. Approval exception not recorded (Assumption-based).
A20: Receipt required above (INR) | B20: 500 | C20: TP-09 | D20: Amount above this with no receipt = Violation; exactly this value = Compliant.
A21: Late if gap above (days) | B21: 15 | C21: TP-10 | D21: Gap = claim_submitted_date - trip_end_date, calendar days. trip_end_date treated as return date.
A22: Expired if gap above (days) | B22: 60 | C22: TP-10 | D22: Above this the TP-10 label is Expired; above Late threshold up to this is Late.
A24: 4. Labels used by the formulas (must match the text in the Claims sheet)
A25: Label | B25: Value
A26: Expense type: Flight | B26: Flight
A27: Expense type: Hotel | B27: Hotel
A28: Expense type: Meals/DA | B28: Meals/DA
A29: Expense type: Alcohol | B29: Alcohol
A30: City class: Metro | B30: Metro
A31: City class: Non-metro | B31: Non-metro
A32: Flight class: Business | B32: Business
A33: Receipt not attached | B33: No
A34: Business not permitted (flag in table 1) | B34: No
A35: Violation | B35: Violation
A36: Compliant | B36: Compliant
... A41: Basis: Assumption-based | B41: Assumption-based
A43: 5. Basis of each rule (claim Basis = Definite if any broken rule is Definite, otherwise Assumption-based)
A44: Rule ID | B44: Basis | C44: Note
A45: TP-01 | B45: =Lbl_Definite -> Definite | C45: Only M1-M3 Business is a violation.
A46: TP-02 | B46: =Lbl_Assumption -> Assumption-based | C46: Approved exception not recorded.
A47: TP-04 | B47: =Lbl_Assumption -> Assumption-based | C47: One claim = one night.
A48: TP-05 | B48: =Lbl_Assumption -> Assumption-based | C48: One claim = one night.
A49: TP-06 | B49: =Lbl_Assumption -> Assumption-based | C49: One claim = one day.
...

Sheet Checker
A1: Checker - one row per claim (formulas only; inputs on the Parameters sheet)
A2: Each rule column shows Violation, Compliant, or n/a (rule does not apply to that expense type). "Compliant" in Status means no violation among the 8 checked rules; the 7 Not checked rules are listed below the table.
I4: Rule basis: | J4: =INDEX(Rule_Basis,MATCH(J5,Rule_IDs,0)) -> Definite | K4: =INDEX(Rule_Basis,MATCH(K5,Rule_IDs,0)) -> Assumption-based | L4: =INDEX(Rule_Basis,MATCH(L5,Rule_IDs,0)) -> Assumption-based | M4: =INDEX(Rule_Basis,MATCH(M5,Rule_IDs,0)) -> Assumption-based | N4: =INDEX(Rule_Basis,MATCH(N5,Rule_IDs,0)) -> Assumption-based | O4: =INDEX(Rule_Basis,MATCH(O5,Rule_IDs,0)) -> Definite | P4: =INDEX(Rule_Basis,MATCH(P5,Rule_IDs,0)) -> Definite | Q4: =INDEX(Rule_Basis,MATCH(Q5,Rule_IDs,0)) -> Definite
A5: claim_id | B5: grade | C5: expense_type | D5: city_class | E5: amount_inr | F5: receipt_attached | G5: days_booked_before_flight | H5: flight_class | I5: gap_days | J5: =Parameters!$A$45 -> TP-01 | K5: =Parameters!$A$46 -> TP-02 | L5: =Parameters!$A$47 -> TP-04 | M5: =Parameters!$A$48 -> TP-05 | N5: =Parameters!$A$49 -> TP-06 | O5: =Parameters!$A$50 -> TP-08 | P5: =Parameters!$A$51 -> TP-09 | Q5: =Parameters!$A$52 -> TP-10 | R5: Status | S5: Rules broken | T5: TP-10 label | U5: Basis | V5: Min nights/days to comply | W5: Review note
A6: =Claims!A2 -> EXP00001 | B6: =Claims!D2 -> M3 | C6: =Claims!E2 -> Meals/DA | D6: =Claims!G2 -> Non-metro | E6: =Claims!H2 -> 1358 | F6: =Claims!K2 -> No | G6: =IF(Claims!M2="","",Claims!M2) | H6: =IF(Claims!N2="","",Claims!N2) | I6: =Claims!J2-Claims!I2 -> 2 | J6: =IF(C6=Lbl_Flight,IF(AND(H6=Lbl_Business,INDEX(Biz_Permitted,MATCH(B6,Caps_Grade,0))=Lbl_BizNo),Lbl_Viol,Lbl_Comp),Lbl_NA) -> n/a | K6: =IF(C6=Lbl_Flight,IF(G6<Min_Days_Booked,Lbl_Viol,Lbl_Comp),Lbl_NA) -> n/a | L6: =IF(AND(C6=Lbl_Hotel,D6=Lbl_Metro),IF(E6>INDEX(Caps_Metro,MATCH(B6,Caps_Grade,0)),Lbl_Viol,Lbl_Comp),Lbl_NA) -> n/a | M6: =IF(AND(C6=Lbl_Hotel,D6=Lbl_NonMetro),IF(E6>INDEX(Caps_NonMetro,MATCH(B6,Caps_Grade,0)),Lbl_Viol,Lbl_Comp),Lbl_NA) -> n/a | N6: =IF(C6=Lbl_Meals,IF(E6>IF(D6=Lbl_Metro,Limit_Metro,Limit_NonMetro),Lbl_Viol,Lbl_Comp),Lbl_NA) -> Violation | O6: =IF(C6=Lbl_Alcohol,Lbl_Viol,Lbl_NA) -> n/a | P6: =IF(AND(F6=Lbl_NoReceipt,E6>Receipt_Threshold),Lbl_Viol,Lbl_Comp) -> Violation | Q6: =IF(I6>Late_Days,Lbl_Viol,Lbl_Comp) -> Compliant | R6: =IF(COUNTIF(J6:Q6,Lbl_Viol)>0,Lbl_Viol,Lbl_Comp) -> Violation | S6: =_xlfn.TEXTJOIN(", ",TRUE(),IF(J6=Lbl_Viol,J$5,""),IF(K6=Lbl_Viol,K$5,""),IF(L6=Lbl_Viol,L$5,""),IF(M6=Lbl_Viol,M$5,""),IF(N6=Lbl_Viol,N$5,""),IF(O6=Lbl_Viol,O$5,""),IF(P6=Lbl_Viol,P$5,""),IF(Q6=Lbl_Viol,Q$5,"")) -> TP-06, TP-09 | T6: =IF(Q6=Lbl_Viol,IF(I6>Expired_Days,Lbl_Expired,Lbl_Late),"") | U6: =IF(R6=Lbl_Comp,"",IF(SUMPRODUCT((J6:Q6=Lbl_Viol)*(J$4:Q$4=Lbl_Definite))>0,Lbl_Definite,Lbl_Assumption)) -> Definite | V6: =IF(L6=Lbl_Viol,ROUNDUP(E6/INDEX(Caps_Metro,MATCH(B6,Caps_Grade,0)),0),IF(M6=Lbl_Viol,ROUNDUP(E6/INDEX(Caps_NonMetro,MATCH(B6,Caps_Grade,0)),0),IF(N6=Lbl_Viol,ROUNDUP(E6/IF(D6=Lbl_Metro,Limit_Metro,Limit_NonMetro),0),""))) -> 2 | W6: =IF(OR(L6=Lbl_Viol,M6=Lbl_Viol),Lbl_NeedNights,IF(N6=Lbl_Viol,Lbl_NeedDays,IF(K6=Lbl_Viol,Lbl_NeedApproval,""))) -> Needs days
A7: =Claims!A3 -> EXP00002 | B7: =Claims!D3 -> M1 | C7: =Claims!E3 -> Hotel | D7: =Claims!G3 -> Non-metro | E7: =Claims!H3 -> 8815 | F7: =Claims!K3 -> Yes | G7: =IF(Claims!M3="","",Claims!M3) | H7: =IF(Claims!N3="","",Claims!N3) | I7: =Claims!J3-Claims!I3 -> 5 | J7: =IF(C7=Lbl_Flight,IF(AND(H7=Lbl_Business,INDEX(Biz_Permitted,MATCH(B7,Caps_Grade,0))=Lbl_BizNo),Lbl_Viol,Lbl_Comp),Lbl_NA) -> n/a | K7: =IF(C7=Lbl_Flight,IF(G7<Min_Days_Booked,Lbl_Viol,Lbl_Comp),Lbl_NA) -> n/a | L7: =IF(AND(C7=Lbl_Hotel,D7=Lbl_Metro),IF(E7>INDEX(Caps_Metro,MATCH(B7,Caps_Grade,0)),Lbl_Viol,Lbl_Comp),Lbl_NA) -> n/a | M7: =IF(AND(C7=Lbl_Hotel,D7=Lbl_NonMetro),IF(E7>INDEX(Caps_NonMetro,MATCH(B7,Caps_Grade,0)),Lbl_Viol,Lbl_Comp),Lbl_NA) -> Violation | N7: =IF(C7=Lbl_Meals,IF(E7>IF(D7=Lbl_Metro,Limit_Metro,Limit_NonMetro),Lbl_Viol,Lbl_Comp),Lbl_NA) -> n/a | O7: =IF(C7=Lbl_Alcohol,Lbl_Viol,Lbl_NA) -> n/a | P7: =IF(AND(F7=Lbl_NoReceipt,E7>Receipt_Threshold),Lbl_Viol,Lbl_Comp) -> Compliant | Q7: =IF(I7>Late_Days,Lbl_Viol,Lbl_Comp) -> Compliant | R7: =IF(COUNTIF(J7:Q7,Lbl_Viol)>0,Lbl_Viol,Lbl_Comp) -> Violation | S7: =_xlfn.TEXTJOIN(", ",TRUE(),IF(J7=Lbl_Viol,J$5,""),IF(K7=Lbl_Viol,K$5,""),IF(L7=Lbl_Viol,L$5,""),IF(M7=Lbl_Viol,M$5,""),IF(N7=Lbl_Viol,N$5,""),IF(O7=Lbl_Viol,O$5,""),IF(P7=Lbl_Viol,P$5,""),IF(Q7=Lbl_Viol,Q$5,"")) -> TP-05 | T7: =IF(Q7=Lbl_Viol,IF(I7>Expired_Days,Lbl_Expired,Lbl_Late),"") | U7: =IF(R7=Lbl_Comp,"",IF(SUMPRODUCT((J7:Q7=Lbl_Viol)*(J$4:Q$4=Lbl_Definite))>0,Lbl_Definite,Lbl_Assumption)) -> Assumption-based | V7: =IF(L7=Lbl_Viol,ROUNDUP(E7/INDEX(Caps_Metro,MATCH(B7,Caps_Grade,0)),0),IF(M7=Lbl_Viol,ROUNDUP(E7/INDEX(Caps_NonMetro,MATCH(B7,Caps_Grade,0)),0),IF(N7=Lbl_Viol,ROUNDUP(E7/IF(D7=Lbl_Metro,Limit_Metro,Limit_NonMetro),0),""))) -> 2 | W7: =IF(OR(L7=Lbl_Viol,M7=Lbl_Viol),Lbl_NeedNights,IF(N7=Lbl_Viol,Lbl_NeedDays,IF(K7=Lbl_Viol,Lbl_NeedApproval,""))) -> Needs nights
A8: =Claims!A4 -> EXP00003 | B8: =Claims!D4 -> M2 | C8: =Claims!E4 -> Local Cab | D8: =Claims!G4 -> Metro | E8: =Claims!H4 -> 1354 | F8: =Claims!K4 -> No | G8: =IF(Claims!M4="","",Claims!M4) | H8: =IF(Claims!N4="","",Claims!N4) | I8: =Claims!J4-Claims!I4 -> 70 | J8: =IF(C8=Lbl_Flight,IF(AND(H8=Lbl_Business,INDEX(Biz_Permitted,MATCH(B8,Caps_Grade,0))=Lbl_BizNo),Lbl_Viol,Lbl_Comp),Lbl_NA) -> n/a | K8: =IF(C8=Lbl_Flight,IF(G8<Min_Days_Booked,Lbl_Viol,Lbl_Comp),Lbl_NA) -> n/a | L8: =IF(AND(C8=Lbl_Hotel,D8=Lbl_Metro),IF(E8>INDEX(Caps_Metro,MATCH(B8,Caps_Grade,0)),Lbl_Viol,Lbl_Comp),Lbl_NA) -> n/a | M8: =IF(AND(C8=Lbl_Hotel,D8=Lbl_NonMetro),IF(E8>INDEX(Caps_NonMetro,MATCH(B8,Caps_Grade,0)),Lbl_Viol,Lbl_Comp),Lbl_NA) -> n/a | N8: =IF(C8=Lbl_Meals,IF(E8>IF(D8=Lbl_Metro,Limit_Metro,Limit_NonMetro),Lbl_Viol,Lbl_Comp),Lbl_NA) -> n/a | O8: =IF(C8=Lbl_Alcohol,Lbl_Viol,Lbl_NA) -> n/a | P8: =IF(AND(F8=Lbl_NoReceipt,E8>Receipt_Threshold),Lbl_Viol,Lbl_Comp) -> Violation | Q8: =IF(I8>Late_Days,Lbl_Viol,Lbl_Comp) -> Violation | R8: =IF(COUNTIF(J8:Q8,Lbl_Viol)>0,Lbl_Viol,Lbl_Comp) -> Violation | S8: =_xlfn.TEXTJOIN(", ",TRUE(),IF(J8=Lbl_Viol,J$5,""),IF(K8=Lbl_Viol,K$5,""),IF(L8=Lbl_Viol,L$5,""),IF(M8=Lbl_Viol,M$5,""),IF(N8=Lbl_Viol,N$5,""),IF(O8=Lbl_Viol,O$5,""),IF(P8=Lbl_Viol,P$5,""),IF(Q8=Lbl_Viol,Q$5,"")) -> TP-09, TP-10 | T8: =IF(Q8=Lbl_Viol,IF(I8>Expired_Days,Lbl_Expired,Lbl_Late),"") -> Expired | U8: =IF(R8=Lbl_Comp,"",IF(SUMPRODUCT((J8:Q8=Lbl_Viol)*(J$4:Q$4=Lbl_Definite))>0,Lbl_Definite,Lbl_Assumption)) -> Definite | V8: =IF(L8=Lbl_Viol,ROUNDUP(E8/INDEX(Caps_Metro,MATCH(B8,Caps_Grade,0)),0),IF(M8=Lbl_Viol,ROUNDUP(E8/INDEX(Caps_NonMetro,MATCH(B8,Caps_Grade,0)),0),IF(N8=Lbl_Viol,ROUNDUP(E8/IF(D8=Lbl_Metro,Limit_Metro,Limit_NonMetro),0),""))) | W8: =IF(OR(L8=Lbl_Viol,M8=Lbl_Viol),Lbl_NeedNights,IF(N8=Lbl_Viol,Lbl_NeedDays,IF(K8=Lbl_Viol,Lbl_NeedApproval,"")))
A9: =Claims!A5 -> EXP00004 | B9: =Claims!D5 -> M1 | C9: =Claims!E5 -> Hotel | D9: =Claims!G5 -> Metro | E9: =Claims!H5 -> 8155 | F9: =Claims!K5 -> Yes | G9: =IF(Claims!M5="","",Claims!M5) | H9: =IF(Claims!N5="","",Claims!N5) | I9: =Claims!J5-Claims!I5 -> 9 | J9: =IF(C9=Lbl_Flight,IF(AND(H9=Lbl_Business,INDEX(Biz_Permitted,MATCH(B9,Caps_Grade,0))=Lbl_BizNo),Lbl_Viol,Lbl_Comp),Lbl_NA) -> n/a | K9: =IF(C9=Lbl_Flight,IF(G9<Min_Days_Booked,Lbl_Viol,Lbl_Comp),Lbl_NA) -> n/a | L9: =IF(AND(C9=Lbl_Hotel,D9=Lbl_Metro),IF(E9>INDEX(Caps_Metro,MATCH(B9,Caps_Grade,0)),Lbl_Viol,Lbl_Comp),Lbl_NA) -> Violation | M9: =IF(AND(C9=Lbl_Hotel,D9=Lbl_NonMetro),IF(E9>INDEX(Caps_NonMetro,MATCH(B9,Caps_Grade,0)),Lbl_Viol,Lbl_Comp),Lbl_NA) -> n/a | N9: =IF(C9=Lbl_Meals,IF(E9>IF(D9=Lbl_Metro,Limit_Metro,Limit_NonMetro),Lbl_Viol,Lbl_Comp),Lbl_NA) -> n/a | O9: =IF(C9=Lbl_Alcohol,Lbl_Viol,Lbl_NA) -> n/a | P9: =IF(AND(F9=Lbl_NoReceipt,E9>Receipt_Threshold),Lbl_Viol,Lbl_Comp) -> Compliant | Q9: =IF(I9>Late_Days,Lbl_Viol,Lbl_Comp) -> Compliant | R9: =IF(COUNTIF(J9:Q9,Lbl_Viol)>0,Lbl_Viol,Lbl_Comp) -> Violation | S9: =_xlfn.TEXTJOIN(", ",TRUE(),IF(J9=Lbl_Viol,J$5,""),IF(K9=Lbl_Viol,K$5,""),IF(L9=Lbl_Viol,L$5,""),IF(M9=Lbl_Viol,M$5,""),IF(N9=Lbl_Viol,N$5,""),IF(O9=Lbl_Viol,O$5,""),IF(P9=Lbl_Viol,P$5,""),IF(Q9=Lbl_Viol,Q$5,"")) -> TP-04 | T9: =IF(Q9=Lbl_Viol,IF(I9>Expired_Days,Lbl_Expired,Lbl_Late),"") | U9: =IF(R9=Lbl_Comp,"",IF(SUMPRODUCT((J9:Q9=Lbl_Viol)*(J$4:Q$4=Lbl_Definite))>0,Lbl_Definite,Lbl_Assumption)) -> Assumption-based | V9: =IF(L9=Lbl_Viol,ROUNDUP(E9/INDEX(Caps_Metro,MATCH(B9,Caps_Grade,0)),0),IF(M9=Lbl_Viol,ROUNDUP(E9/INDEX(Caps_NonMetro,MATCH(B9,Caps_Grade,0)),0),IF(N9=Lbl_Viol,ROUNDUP(E9/IF(D9=Lbl_Metro,Limit_Metro,Limit_NonMetro),0),""))) -> 2 | W9: =IF(OR(L9=Lbl_Viol,M9=Lbl_Viol),Lbl_NeedNights,IF(N9=Lbl_Viol,Lbl_NeedDays,IF(K9=Lbl_Viol,Lbl_NeedApproval,""))) -> Needs nights
A10: =Claims!A6 -> EXP00005 | B10: =Claims!D6 -> M5 | C10: =Claims!E6 -> Alcohol | D10: =Claims!G6 -> Metro | E10: =Claims!H6 -> 2069 | F10: =Claims!K6 -> Yes | G10: =IF(Claims!M6="","",Claims!M6) | H10: =IF(Claims!N6="","",Claims!N6) | I10: =Claims!J6-Claims!I6 -> 14 | J10: =IF(C10=Lbl_Flight,IF(AND(H10=Lbl_Business,INDEX(Biz_Permitted,MATCH(B10,Caps_Grade,0))=Lbl_BizNo),Lbl_Viol,Lbl_Comp),Lbl_NA) -> n/a | K10: =IF(C10=Lbl_Flight,IF(G10<Min_Days_Booked,Lbl_Viol,Lbl_Comp),Lbl_NA) -> n/a | L10: =IF(AND(C10=Lbl_Hotel,D10=Lbl_Metro),IF(E10>INDEX(Caps_Metro,MATCH(B10,Caps_Grade,0)),Lbl_Viol,Lbl_Comp),Lbl_NA) -> n/a | M10: =IF(AND(C10=Lbl_Hotel,D10=Lbl_NonMetro),IF(E10>INDEX(Caps_NonMetro,MATCH(B10,Caps_Grade,0)),Lbl_Viol,Lbl_Comp),Lbl_NA) -> n/a | N10: =IF(C10=Lbl_Meals,IF(E10>IF(D10=Lbl_Metro,Limit_Metro,Limit_NonMetro),Lbl_Viol,Lbl_Comp),Lbl_NA) -> n/a | O10: =IF(C10=Lbl_Alcohol,Lbl_Viol,Lbl_NA) -> Violation | P10: =IF(AND(F10=Lbl_NoReceipt,E10>Receipt_Threshold),Lbl_Viol,Lbl_Comp) -> Compliant | Q10: =IF(I10>Late_Days,Lbl_Viol,Lbl_Comp) -> Compliant | R10: =IF(COUNTIF(J10:Q10,Lbl_Viol)>0,Lbl_Viol,Lbl_Comp) -> Violation | S10: =_xlfn.TEXTJOIN(", ",TRUE(),IF(J10=Lbl_Viol,J$5,""),IF(K10=Lbl_Viol,K$5,""),IF(L10=Lbl_Viol,L$5,""),IF(M10=Lbl_Viol,M$5,""),IF(N10=Lbl_Viol,N$5,""),IF(O10=Lbl_Viol,O$5,""),IF(P10=Lbl_Viol,P$5,""),IF(Q10=Lbl_Viol,Q$5,"")) -> TP-08 | T10: =IF(Q10=Lbl_Viol,IF(I10>Expired_Days,Lbl_Expired,Lbl_Late),"") | U10: =IF(R10=Lbl_Comp,"",IF(SUMPRODUCT((J10:Q10=Lbl_Viol)*(J$4:Q$4=Lbl_Definite))>0,Lbl_Definite,Lbl_Assumption)) -> Definite | V10: =IF(L10=Lbl_Viol,ROUNDUP(E10/INDEX(Caps_Metro,MATCH(B10,Caps_Grade,0)),0),IF(M10=Lbl_Viol,ROUNDUP(E10/INDEX(Caps_NonMetro,MATCH(B10,Caps_Grade,0)),0),IF(N10=Lbl_Viol,ROUNDUP(E10/IF(D10=Lbl_Metro,Limit_Metro,Limit_NonMetro),0),""))) | W10: =IF(OR(L10=Lbl_Viol,M10=Lbl_Viol),Lbl_NeedNights,IF(N10=Lbl_Viol,Lbl_NeedDays,IF(K10=Lbl_Viol,Lbl_NeedApproval,"")))
A11: =Claims!A7 -> EXP00006 | B11: =Claims!D7 -> M3 | C11: =Claims!E7 -> Flight | D11: =Claims!G7 -> Non-metro | E11: =Claims!H7 -> 6289 | F11: =Claims!K7 -> Yes | G11: =IF(Claims!M7="","",Claims!M7) -> 3 | H11: =IF(Claims!N7="","",Claims!N7) -> Economy | I11: =Claims!J7-Claims!I7 -> 9 | J11: =IF(C11=Lbl_Flight,IF(AND(H11=Lbl_Business,INDEX(Biz_Permitted,MATCH(B11,Caps_Grade,0))=Lbl_BizNo),Lbl_Viol,Lbl_Comp),Lbl_NA) -> Compliant | K11: =IF(C11=Lbl_Flight,IF(G11<Min_Days_Booked,Lbl_Viol,Lbl_Comp),Lbl_NA) -> Violation | L11: =IF(AND(C11=Lbl_Hotel,D11=Lbl_Metro),IF(E11>INDEX(Caps_Metro,MATCH(B11,Caps_Grade,0)),Lbl_Viol,Lbl_Comp),Lbl_NA) -> n/a | M11: =IF(AND(C11=Lbl_Hotel,D11=Lbl_NonMetro),IF(E11>INDEX(Caps_NonMetro,MATCH(B11,Caps_Grade,0)),Lbl_Viol,Lbl_Comp),Lbl_NA) -> n/a | N11: =IF(C11=Lbl_Meals,IF(E11>IF(D11=Lbl_Metro,Limit_Metro,Limit_NonMetro),Lbl_Viol,Lbl_Comp),Lbl_NA) -> n/a | O11: =IF(C11=Lbl_Alcohol,Lbl_Viol,Lbl_NA) -> n/a | P11: =IF(AND(F11=Lbl_NoReceipt,E11>Receipt_Threshold),Lbl_Viol,Lbl_Comp) -> Compliant | Q11: =IF(I11>Late_Days,Lbl_Viol,Lbl_Comp) -> Compliant | R11: =IF(COUNTIF(J11:Q11,Lbl_Viol)>0,Lbl_Viol,Lbl_Comp) -> Violation | S11: =_xlfn.TEXTJOIN(", ",TRUE(),IF(J11=Lbl_Viol,J$5,""),IF(K11=Lbl_Viol,K$5,""),IF(L11=Lbl_Viol,L$5,""),IF(M11=Lbl_Viol,M$5,""),IF(N11=Lbl_Viol,N$5,""),IF(O11=Lbl_Viol,O$5,""),IF(P11=Lbl_Viol,P$5,""),IF(Q11=Lbl_Viol,Q$5,"")) -> TP-02 | T11: =IF(Q11=Lbl_Viol,IF(I11>Expired_Days,Lbl_Expired,Lbl_Late),"") | U11: =IF(R11=Lbl_Comp,"",IF(SUMPRODUCT((J11:Q11=Lbl_Viol)*(J$4:Q$4=Lbl_Definite))>0,Lbl_Definite,Lbl_Assumption)) -> Assumption-based | V11: =IF(L11=Lbl_Viol,ROUNDUP(E11/INDEX(Caps_Metro,MATCH(B11,Caps_Grade,0)),0),IF(M11=Lbl_Viol,ROUNDUP(E11/INDEX(Caps_NonMetro,MATCH(B11,Caps_Grade,0)),0),IF(N11=Lbl_Viol,ROUNDUP(E11/IF(D11=Lbl_Metro,Limit_Metro,Limit_NonMetro),0),""))) | W11: =IF(OR(L11=Lbl_Viol,M11=Lbl_Viol),Lbl_NeedNights,IF(N11=Lbl_Viol,Lbl_NeedDays,IF(K11=Lbl_Viol,Lbl_NeedApproval,""))) -> Needs approval
A12: =Claims!A8 -> EXP00007 | B12: =Claims!D8 -> M1 | C12: =Claims!E8 -> Stationery | D12: =Claims!G8 -> Non-metro | E12: =Claims!H8 -> 966 | F12: =Claims!K8 -> Yes | G12: =IF(Claims!M8="","",Claims!M8) | H12: =IF(Claims!N8="","",Claims!N8) | I12: =Claims!J8-Claims!I8 -> 2 | J12: =IF(C12=Lbl_Flight,IF(AND(H12=Lbl_Business,INDEX(Biz_Permitted,MATCH(B12,Caps_Grade,0))=Lbl_BizNo),Lbl_Viol,Lbl_Comp),Lbl_NA) -> n/a | K12: =IF(C12=Lbl_Flight,IF(G12<Min_Days_Booked,Lbl_Viol,Lbl_Comp),Lbl_NA) -> n/a | L12: =IF(AND(C12=Lbl_Hotel,D12=Lbl_Metro),IF(E12>INDEX(Caps_Metro,MATCH(B12,Caps_Grade,0)),Lbl_Viol,Lbl_Comp),Lbl_NA) -> n/a | M12: =IF(AND(C12=Lbl_Hotel,D12=Lbl_NonMetro),IF(E12>INDEX(Caps_NonMetro,MATCH(B12,Caps_Grade,0)),Lbl_Viol,Lbl_Comp),Lbl_NA) -> n/a | N12: =IF(C12=Lbl_Meals,IF(E12>IF(D12=Lbl_Metro,Limit_Metro,Limit_NonMetro),Lbl_Viol,Lbl_Comp),Lbl_NA) -> n/a | O12: =IF(C12=Lbl_Alcohol,Lbl_Viol,Lbl_NA) -> n/a | P12: =IF(AND(F12=Lbl_NoReceipt,E12>Receipt_Threshold),Lbl_Viol,Lbl_Comp) -> Compliant | Q12: =IF(I12>Late_Days,Lbl_Viol,Lbl_Comp) -> Compliant | R12: =IF(COUNTIF(J12:Q12,Lbl_Viol)>0,Lbl_Viol,Lbl_Comp) -> Compliant | S12: =_xlfn.TEXTJOIN(", ",TRUE(),IF(J12=Lbl_Viol,J$5,""),IF(K12=Lbl_Viol,K$5,""),IF(L12=Lbl_Viol,L$5,""),IF(M12=Lbl_Viol,M$5,""),IF(N12=Lbl_Viol,N$5,""),IF(O12=Lbl_Viol,O$5,""),IF(P12=Lbl_Viol,P$5,""),IF(Q12=Lbl_Viol,Q$5,"")) | T12: =IF(Q12=Lbl_Viol,IF(I12>Expired_Days,Lbl_Expired,Lbl_Late),"") | U12: =IF(R12=Lbl_Comp,"",IF(SUMPRODUCT((J12:Q12=Lbl_Viol)*(J$4:Q$4=Lbl_Definite))>0,Lbl_Definite,Lbl_Assumption)) | V12: =IF(L12=Lbl_Viol,ROUNDUP(E12/INDEX(Caps_Metro,MATCH(B12,Caps_Grade,0)),0),IF(M12=Lbl_Viol,ROUNDUP(E12/INDEX(Caps_NonMetro,MATCH(B12,Caps_Grade,0)),0),IF(N12=Lbl_Viol,ROUNDUP(E12/IF(D12=Lbl_Metro,Limit_Metro,Limit_NonMetro),0),""))) | W12: =IF(OR(L12=Lbl_Viol,M12=Lbl_Viol),Lbl_NeedNights,IF(N12=Lbl_Viol,Lbl_NeedDays,IF(K12=Lbl_Viol,Lbl_NeedApproval,"")))
